<?xml version="1.0"?>
<robot name="Explorer_bot">

    
    <link name="base_link">
        <visual>
            <geometry>
                <box size="0.6 0.3 0.1"/>
            </geometry>
            <material name="grey">
                <color rgba="0.5 0.0 0.5 1"/>
            </material>
        </visual>
        <collision>
            <geometry>
                <box size="0.6 0.3 0.1"/>
            </geometry>
        </collision>
        <inertial>
            <mass value="1.0"/>
            <inertia ixx="0.00308" ixy="0" ixz="0" iyy="0.0375" iyz="0.0" izz="0.0833"/>
        </inertial>
        
    </link>



    

<link name="right_back_wheel">
        <visual>
            <geometry>
                <cylinder radius="0.035" length="0.05"/>
            </geometry>
            <material name="black">
                <color rgba="0.0 0.0 0.0 1"/>
            </material>

        </visual>
        <collision>
            <geometry>
                <cylinder radius="0.035" length="0.05"/>
            </geometry>
        </collision>
        <inertial>
            <mass value="0.1"/>
            <inertia ixx="5.1458e-5" ixy="0" ixz="0" iyy="5.1458e-5" iyz="0.0" izz="6.125e-5"/>        </inertial>
    </link>


    <link name="right_front_wheel">
        <visual>
            <geometry>
                <cylinder radius="0.035" length="0.05"/>
            </geometry>
            <material name="black">
                <color rgba="0.0 0.0 0.0 1"/>
            </material>

        </visual>
        <collision>
            <geometry>
                <cylinder radius="0.035" length="0.05"/>
            </geometry>
        </collision>
        <inertial>
            <mass value="0.1"/>
            <inertia ixx="5.1458e-5" ixy="0" ixz="0" iyy="5.1458e-5" iyz="0.0" izz="6.125e-5"/>        </inertial>
    </link>


    <joint name="right_back_wheel_to_base_joint" type="continuous">
        <axis xyz="0.0 0.0 1"/>
        <parent link="base_link"/>
        <child link="right_back_wheel"/>
        <origin xyz="-0.2825 -0.125 -0.05" rpy="-1.5708 0.0 0.0"/>
        
    </joint>


    <joint name="right_wheel_joint" type="continuous">
        <axis xyz="0.0 0.0 1"/>
        <parent link="base_link"/>
        <child link="right_front_wheel"/>
        <origin xyz="0.2825 -0.125 -0.05" rpy="-1.5708 0.0 0.0"/>
        
    </joint>




    <link name="left_back_wheel">
        <visual>
            <geometry>
                <cylinder radius="0.035" length="0.05"/>
            </geometry>
            <material name="black">
                <color rgba="0.0 0.0 0.0 1"/>
            </material>

        </visual>
        <collision>
            <geometry>
                <cylinder radius="0.035" length="0.05"/>
            </geometry>
        </collision>
        <inertial>
            <mass value="0.1"/>
            <inertia ixx="5.1458e-5" ixy="0" ixz="0" iyy="5.1458e-5" iyz="0.0" izz="6.125e-5"/>        </inertial>
    </link>


    <link name="left_front_wheel">
        <visual>
            <geometry>
                <cylinder radius="0.035" length="0.05"/>
            </geometry>
            <material name="black">
                <color rgba="0.0 0.0 0.0 1"/>
            </material>

        </visual>
        <collision>
            <geometry>
                <cylinder radius="0.035" length="0.05"/>
            </geometry>
        </collision>
        <inertial>
            <mass value="0.1"/>
            <inertia ixx="5.1458e-5" ixy="0" ixz="0" iyy="5.1458e-5" iyz="0.0" izz="6.125e-5"/>        </inertial>
    </link>


    <joint name="left_back_wheel_to_base_joint" type="continuous">
        <axis xyz="0.0 0.0 1"/>
        <parent link="base_link"/>
        <child link="left_back_wheel"/>
        <origin xyz="-0.2825 0.125 -0.05" rpy="-1.5708 0.0 0.0"/>
        
    </joint>

    <joint name="left_wheel_joint" type="continuous">
        <axis xyz="0.0 0.0 1"/>
        <parent link="base_link"/>
        <child link="left_front_wheel"/>
        <origin xyz="0.2825 0.125 -0.05" rpy="-1.5708 0.0 0.0"/>
        
    </joint>


    

    

    <link name="laser_scanner">
        <visual>
            <geometry>
                <box size="0.1 0.1 0.1"/>
            </geometry>
        </visual>

        <collision>
            <geometry>
                <box size="0.1 0.1 0.1"/>
            </geometry>
        </collision>

        <inertial>
            <mass value="1e-5"/>
            <inertia ixx="1e-6" ixy="0" ixz="0.0" iyy="1e-6" iyz="0.0" izz="1e-6"/>
        </inertial>
    </link>

    <joint name="laser_scanner_joint" type="fixed">
        <axis xyz="0.0 1 0.0"/>
        <parent link="base_link"/>
        <child link="laser_scanner"/>
        <origin xyz="0.0 0.0 0.08" rpy="0.0 0.0 0.0"/>
    </joint>

    <gazebo reference="laser_scanner">
        <sensor type="ray" name="laser">
            <pose>0 0 0 0 0 0</pose>
            <visualize>true</visualize>
            <update_rate>40</update_rate>
            <ray>
                <scan>
                    <horizontal>
                        <samples>720</samples>
                        <resolution>1</resolution>
                        <min_angle>-1.578</min_angle>
                        <max_angle>1.578</max_angle>
                    </horizontal>
                </scan>
                <range>
                    <min>0.1</min>
                    <max>10</max>
                    <resolution>0.1</resolution>
                </range>
            </ray>
            <plugin name="Lidar" filename="libgazebo_ros_laser.so">
                <topicName>/scan</topicName>
                <frameName>laser_scanner</frameName>
            </plugin>
        </sensor>
    </gazebo>


    <gazebo>
        <plugin name="explorer_bot_controller"   filename="libgazebo_ros_diff_drive.so">
            <leftJoint>left_front_wheel_joint</leftJoint>
            <rightJoint>right_front_wheel_joint</rightJoint>
            <legacyMode>false</legacyMode>
            <robotBaseFrame>base_link</robotBaseFrame>
            <wheelSeparation>0.25</wheelSeparation>
            <wheelDiameter>0.07</wheelDiameter>
            <publishWheelJointState>true</publishWheelJointState>
        </plugin>
        
    </gazebo>
       <gazebo>
        <plugin name="joint_state_publisher"
                filename="libgazebo_ros_joint_state_publisher.so">
            <jointName>left_back_wheel_to_base_joint, left_back_wheel_to_base_joint</jointName>
        </plugin>
    </gazebo>


   


    <gazebo reference="base_link">
        <material>Gazebo/Purple</material>
    </gazebo>
    <gazebo reference="left_front_wheel">
        <material>Gazebo/Black</material>
      </gazebo>
      <gazebo reference="left_back_wheel">
        <material>Gazebo/Black</material>
      </gazebo>
      <gazebo reference="right_front_wheel">
        <material>Gazebo/Black</material>
      </gazebo>
      <gazebo reference="right_back_wheel">
        <material>Gazebo/Black</material>
      </gazebo>





    </robot>
